#VRML_SIM R2023a utf8

EXTERNPROTO "https://raw.githubusercontent.com/cyberbotics/webots/R2023a/projects/objects/backgrounds/protos/TexturedBackground.proto"
EXTERNPROTO "https://raw.githubusercontent.com/cyberbotics/webots/R2023a/projects/objects/backgrounds/protos/TexturedBackgroundLight.proto"
EXTERNPROTO "https://raw.githubusercontent.com/cyberbotics/webots/R2023a/projects/objects/floors/protos/RectangleArena.proto"
IMPORTABLE EXTERNPROTO "../protos/FourWheelsRobot.proto"

WorldInfo {
  ERP 0.6
  basicTimeStep 8
}
Viewpoint {
  orientation -0.004481641396400818 -0.9999728785446809 0.00584440462829671 4.975424600132727
  position -0.15900107770173133 -0.0035545088653825673 0.2452726566778514
}
TexturedBackground {
}
TexturedBackgroundLight {
  castShadows FALSE
}
RectangleArena {
  translation -0.0103801 0.0164444 -0.01
  rotation 0 1 0 0
  floorSize 1.3 1.3
  floorAppearance Appearance {
    material Material {
      shininess 0
    }
    texture ImageTexture {
      url [
        "../libraries/Dojo.jpeg"
      ]
      repeatS FALSE
      repeatT FALSE
    }
    textureTransform TextureTransform {
      scale 0.39 0.39
    }
  }
}
Robot {
  translation -0.5415308573198703 -0.420641868525868 -0.00999914660691175
  rotation 0.00036453330578887686 -0.039284628871565565 -0.9992279945287224 0.0011023316045104977
  children [
    Accelerometer {
      translation 0.009 0.019 0.0302
      children [
        Solid {
          children [
            Shape {
              appearance PBRAppearance {
                baseColor 0 0 0
              }
              geometry Box {
                size 0.002 0.002 0.0005
              }
            }
          ]
          boundingObject Box {
            size 0.002 0.002 0.0005
          }
          physics Physics {
            mass 1e-08
          }
        }
      ]
      boundingObject Box {
        size 0.002 0.002 0.0005
      }
      physics Physics {
        mass 1e-08
      }
    }
    Gyro {
      translation 0.006 0.016 0.0302
      children [
        Solid {
          children [
            Shape {
              appearance PBRAppearance {
                baseColor 0 0 0
              }
              geometry Box {
                size 0.002 0.002 0.0005
              }
            }
          ]
          boundingObject Box {
            size 0.002 0.002 0.0005
          }
          physics Physics {
            mass 1e-08
          }
        }
      ]
      boundingObject Box {
        size 0.002 0.002 0.0005
      }
      physics Physics {
        mass 1e-08
      }
    }
    Compass {
      translation 0.009 0.016 0.0302
      children [
        Solid {
          children [
            Shape {
              appearance PBRAppearance {
                baseColor 0 0 0
              }
              geometry Box {
                size 0.002 0.002 0.0005
              }
            }
          ]
          boundingObject Box {
            size 0.002 0.002 0.0005
          }
          physics Physics {
            mass 1e-08
          }
        }
      ]
      boundingObject Box {
        size 0.002 0.002 0.0005
      }
      physics Physics {
        mass 1e-08
      }
    }
    DistanceSensor {
      translation 0.05 0.03 0.005
      rotation 0 1 0 1.57
      children [
        Solid {
          rotation 0 1 0 -1.57
          children [
            Shape {
              appearance PBRAppearance {
                baseColor 0 0 0
              }
              geometry Box {
                size 0.002 0.002 0.0005
              }
            }
          ]
          boundingObject Box {
            size 0.002 0.002 0.0005
          }
          physics Physics {
            mass 1e-08
          }
        }
      ]
      name "front_line"
      boundingObject Box {
        size 0.0005 0.002 0.002
      }
      physics Physics {
        mass 1e-08
      }
      type "infra-red"
    }
    DistanceSensor {
      translation 0.05 -0.012 0.005
      rotation 0 1 0 1.57
      children [
        Solid {
          rotation 0 1 0 -1.57
          children [
            Shape {
              appearance PBRAppearance {
                baseColor 0 0 0
              }
              geometry Box {
                size 0.002 0.002 0.0005
              }
            }
          ]
          boundingObject Box {
            size 0.002 0.002 0.0005
          }
          physics Physics {
            mass 1e-08
          }
        }
      ]
      name "right_line"
      boundingObject Box {
        size 0.0005 0.002 0.002
      }
      physics Physics {
        mass 1e-08
      }
      type "infra-red"
    }
    DistanceSensor {
      translation 0.05 0.072 0.005
      rotation 0 1 0 1.57
      children [
        Solid {
          rotation 0 1 0 -1.57
          children [
            Shape {
              appearance PBRAppearance {
                baseColor 0 0 0
              }
              geometry Box {
                size 0.002 0.002 0.0005
              }
            }
          ]
          boundingObject Box {
            size 0.002 0.002 0.0005
          }
          physics Physics {
            mass 1e-08
          }
        }
      ]
      name "left_line"
      boundingObject Box {
        size 0.0005 0.002 0.002
      }
      physics Physics {
        mass 1e-08
      }
      type "infra-red"
    }
    DistanceSensor {
      translation 0.05 0.023 0.005
      rotation 0 1 0 1.57
      children [
        Solid {
          rotation 0 1 0 -1.57
          children [
            Shape {
              appearance PBRAppearance {
                baseColor 0 0 0
              }
              geometry Box {
                size 0.002 0.002 0.0005
              }
            }
          ]
          boundingObject Box {
            size 0.002 0.002 0.0005
          }
          physics Physics {
            mass 1e-08
          }
        }
      ]
      name "front-right_line"
      boundingObject Box {
        size 0.0005 0.002 0.002
      }
      physics Physics {
        mass 1e-08
      }
      type "infra-red"
    }
    DistanceSensor {
      translation 0.05 0.037 0.005
      rotation 0 1 0 1.57
      children [
        Solid {
          rotation 0 1 0 -1.57
          children [
            Shape {
              appearance PBRAppearance {
                baseColor 0 0 0
              }
              geometry Box {
                size 0.002 0.002 0.0005
              }
            }
          ]
          boundingObject Box {
            size 0.002 0.002 0.0005
          }
          physics Physics {
            mass 1e-08
          }
        }
      ]
      name "front-left_line"
      boundingObject Box {
        size 0.0005 0.002 0.002
      }
      physics Physics {
        mass 1e-08
      }
      type "infra-red"
    }
    DistanceSensor {
      translation 0.05 -0.005 0.006
      rotation 0 0 1 -1.57
      children [
        Solid {
          rotation 1 0 0 1.57
          children [
            Shape {
              appearance PBRAppearance {
                baseColor 0 0 0
              }
              geometry Capsule {
                height 0.001
                radius 0.001
              }
            }
          ]
          boundingObject Capsule {
            height 0.001
            radius 0.001
            subdivision 16
          }
          physics Physics {
            mass 1e-08
          }
        }
      ]
      name "right_distance"
      boundingObject Capsule {
        height 0.001
        radius 0.001
        subdivision 16
      }
      physics Physics {
        mass 8.1e-07
      }
      lookupTable [
        0.04 0 0
        0.3 1000 0
      ]
    }
    DistanceSensor {
      translation 0.05 0.065 0.006
      rotation 0 0 1 1.57
      children [
        Solid {
          rotation 1 0 0 1.57
          children [
            Shape {
              appearance PBRAppearance {
                baseColor 0 0 0
              }
              geometry Capsule {
                height 0.001
                radius 0.001
              }
            }
          ]
          boundingObject Capsule {
            height 0.001
            radius 0.001
            subdivision 16
          }
          physics Physics {
            mass 1e-08
          }
        }
      ]
      name "left_distance"
      boundingObject Capsule {
        height 0.001
        radius 0.001
        subdivision 16
      }
      physics Physics {
        mass 8.1e-07
      }
      lookupTable [
        0.04 0 0
        0.3 1000 0
      ]
    }
    DistanceSensor {
      translation 0.057 0.03 0.005
      rotation 1 0 0 -1.57
      children [
        Solid {
          rotation 0 0 1 1.57
          children [
            Shape {
              appearance PBRAppearance {
                baseColor 0 0 0
              }
              geometry Capsule {
                height 0.001
                radius 0.001
              }
            }
          ]
          boundingObject Capsule {
            height 0.001
            radius 0.001
            subdivision 16
          }
          physics Physics {
            mass 1e-08
          }
        }
      ]
      name "front_distance"
      boundingObject Capsule {
        height 0.001
        radius 0.001
        subdivision 16
      }
      physics Physics {
        mass 1e-08
      }
      lookupTable [
        0.04 0 0
        0.3 1000 0
      ]
    }
    DEF Body Transform {
      rotation 0 1 0 1.57
      scale 0.001 0.001 0.001
      children [
        Shape {
          appearance PBRAppearance {
            baseColor 0.1 0 0.1
            metalness 0
          }
          geometry Mesh {
            url [
              "../protos/Pololu_no_orugas.obj"
            ]
          }
        }
      ]
    }
    DEF DD HingeJoint {
      jointParameters HingeJointParameters {
        position 83.91999798812314
        axis 0 1 0
        anchor 0.03 -0.00951997 0.018
      }
      device [
        RotationalMotor {
          name "motor3"
        }
        PositionSensor {
          name "encoder3"
        }
      ]
      endPoint Solid {
        translation 0.03 -0.00951997 0.018
        rotation -0.32891036159672393 -0.6680299923384619 0.6674982422228442 3.7775947286664118
        children [
          Shape {
            appearance Appearance {
              material Material {
                diffuseColor 0.1 0.1 0.1
              }
            }
            geometry Cylinder {
              height 0.019
              radius 0.018
            }
          }
        ]
        name "solid(2)"
        boundingObject Cylinder {
          height 0.019
          radius 0.018
        }
        physics Physics {
          mass 1e-05
        }
      }
    }
    DEF DA HingeJoint {
      jointParameters HingeJointParameters {
        position 82.76799783597018
        axis 0 1 0
        anchor -0.018 -0.00951997 0.018
      }
      device [
        RotationalMotor {
          name "motor4"
        }
        PositionSensor {
          name "encoder4"
        }
      ]
      endPoint Solid {
        translation -0.01799990047846152 -0.00951998 0.018000009770536212
        rotation 0.7629039710901154 0.4573348751668609 -0.45697083369843655 1.837407292626431
        children [
          Shape {
            appearance Appearance {
              material Material {
                diffuseColor 0.1 0.1 0.1
              }
            }
            geometry Cylinder {
              height 0.019
              radius 0.018
            }
          }
        ]
        name "solid(3)"
        boundingObject Cylinder {
          height 0.019
          radius 0.018
        }
        physics Physics {
          mass 1e-05
        }
      }
    }
    DEF IA HingeJoint {
      jointParameters HingeJointParameters {
        position 82.76799790095362
        axis 0 1 0
        anchor -0.018 0.07 0.018
      }
      device [
        RotationalMotor {
          name "motor2"
        }
        PositionSensor {
          name "encoder2"
        }
      ]
      endPoint Solid {
        translation -0.017999900478460482 0.07 0.01800000977052568
        rotation -0.7629039399588904 0.45733490120577797 0.4569708596117514 1.8374073188654085
        children [
          Shape {
            appearance Appearance {
              material Material {
                diffuseColor 0.1 0.1 0.1
              }
            }
            geometry Cylinder {
              height 0.019
              radius 0.018
            }
          }
        ]
        name "solid(1)"
        boundingObject Cylinder {
          height 0.019
          radius 0.018
        }
        physics Physics {
          mass 1e-05
        }
      }
    }
    DEF ID HingeJoint {
      jointParameters HingeJointParameters {
        position 83.9199979706598
        axis 0 1 0
        anchor 0.03 0.07 0.018
      }
      device [
        RotationalMotor {
          name "motor1"
        }
        PositionSensor {
          name "encoder1"
        }
      ]
      endPoint Solid {
        translation 0.03 0.07 0.018
        rotation 0.3289103607712409 -0.6680299995434453 -0.6674982354188785 3.777594734111423
        children [
          Shape {
            appearance Appearance {
              material Material {
                diffuseColor 0.1 0.1 0.1
              }
            }
            geometry Cylinder {
              height 0.019
              radius 0.018
            }
          }
        ]
        boundingObject Cylinder {
          height 0.019
          radius 0.018
        }
        physics Physics {
          mass 1e-05
        }
      }
    }
  ]
  name "robot1"
  boundingObject USE Body
  physics Physics {
    mass 0.03
  }
  controller "<none>"
}
DEF Pololu Robot {
  translation -0.14357732924521144 -0.0025388264919883525 0.030505378285948268
  rotation -0.08097804891040883 0.004766589708494407 -0.9967044874069817 0.017873508701199158
  children [
    InertialUnit {
      translation 0.02 -0.02 0.013
      children [
        Solid {
          children [
            DEF IMU Shape {
              appearance Appearance {
                material Material {
                  diffuseColor 0.1 0.1 0.1
                }
              }
              geometry Box {
                size 0.01 0.01 0.001
              }
            }
          ]
          boundingObject USE IMU
          physics Physics {
          }
        }
      ]
      name "IMU"
      boundingObject USE IMU
      physics Physics {
      }
    }
    DistanceSensor {
      translation 0.052 0.008 -0.01006
      rotation 0 1 0 1.572
      children [
        Solid {
          children [
            DEF LFL Shape {
              appearance Appearance {
                material Material {
                  diffuseColor 0.1 0.1 0.1
                }
              }
              geometry Box {
                size 0.001 0.002 0.002
              }
            }
          ]
          boundingObject USE LFL
          physics Physics {
          }
        }
      ]
      name "front_left_line"
      boundingObject USE LFL
      physics Physics {
      }
      type "infra-red"
    }
    DistanceSensor {
      translation 0.052 -0.008 -0.01006
      rotation 0 1 0 1.572
      children [
        Solid {
          children [
            DEF LFR Shape {
              appearance Appearance {
                material Material {
                  diffuseColor 0.1 0.1 0.1
                }
              }
              geometry Box {
                size 0.001 0.002 0.002
              }
            }
          ]
          boundingObject USE LFR
          physics Physics {
          }
        }
      ]
      name "front_right_line"
      boundingObject USE LFR
      physics Physics {
      }
      type "infra-red"
    }
    DistanceSensor {
      translation 0.052 0.04 -0.01006
      rotation 0 1 0 1.572
      children [
        Solid {
          children [
            DEF LL Shape {
              appearance Appearance {
                material Material {
                  diffuseColor 0.1 0.1 0.1
                }
              }
              geometry Box {
                size 0.001 0.002 0.002
              }
            }
          ]
          boundingObject USE LL
          physics Physics {
          }
        }
      ]
      name "left_line"
      boundingObject USE LL
      physics Physics {
      }
      type "infra-red"
    }
    DistanceSensor {
      translation 0.052 -0.04 -0.01006
      rotation 0 1 0 1.572
      children [
        Solid {
          children [
            DEF LR Shape {
              appearance Appearance {
                material Material {
                  diffuseColor 0.1 0.1 0.1
                }
              }
              geometry Box {
                size 0.001 0.002 0.002
              }
            }
          ]
          boundingObject USE LR
          physics Physics {
          }
        }
      ]
      name "right_line"
      boundingObject USE LR
      physics Physics {
      }
      type "infra-red"
    }
    DistanceSensor {
      translation 0.052 0 -0.01006
      rotation 0 1 0 1.572
      children [
        Solid {
          children [
            DEF LF Shape {
              appearance Appearance {
                material Material {
                  diffuseColor 0.1 0.1 0.1
                }
              }
              geometry Box {
                size 0.001 0.002 0.002
              }
            }
          ]
          boundingObject USE LF
          physics Physics {
          }
        }
      ]
      name "front_line"
      boundingObject USE LF
      physics Physics {
      }
      type "infra-red"
    }
    DistanceSensor {
      translation 0.052 -0.043 -0.01
      rotation 0 0 1 -1.572
      children [
        Solid {
          rotation 1 0 0 1.572
          children [
            DEF D2 Shape {
              appearance Appearance {
                material Material {
                  diffuseColor 0.1 0.1 0.1
                }
              }
              geometry Capsule {
                height 0.002
                radius 0.001
              }
            }
          ]
          boundingObject USE D2
          physics Physics {
          }
        }
      ]
      name "right_distance"
      boundingObject USE D2
      physics Physics {
      }
      lookupTable [
        0.04 0 0
        0.3 1000 0
      ]
    }
    DistanceSensor {
      translation 0.051904 0.043 -0.01
      rotation 0 0 1 1.572
      children [
        Solid {
          rotation 1 0 0 1.572
          children [
            DEF D3 Shape {
              appearance Appearance {
                material Material {
                  diffuseColor 0.1 0.1 0.1
                }
              }
              geometry Capsule {
                height 0.002
                radius 0.001
              }
            }
          ]
          boundingObject USE D3
          physics Physics {
          }
        }
      ]
      name "left_distance"
      boundingObject USE D3
      physics Physics {
      }
      lookupTable [
        0.04 0 0
        0.3 1000 0
      ]
    }
    DistanceSensor {
      translation 0.058 0 -0.01
      children [
        Solid {
          rotation 1 0 0 1.572
          children [
            DEF D1 Shape {
              appearance Appearance {
                material Material {
                  diffuseColor 0.1 0.1 0.1
                }
              }
              geometry Capsule {
                height 0.002
                radius 0.001
              }
            }
          ]
          boundingObject USE D1
          physics Physics {
          }
        }
      ]
      name "front_distance"
      boundingObject USE D1
      physics Physics {
      }
      lookupTable [
        0.04 0 0
        0.3 1000 0
      ]
    }
    DEF Ramp Transform {
      translation 0.055 0 0.002
      rotation 0 1 0 -0.2618
      children [
        Solid {
          rotation 0 1 0 0
          children [
            DEF Ramp_model Shape {
              appearance Appearance {
                material Material {
                  diffuseColor 0.1 0.1 0.1
                }
              }
              geometry Box {
                size 0.001 0.1 0.04
              }
            }
          ]
          boundingObject USE Ramp_model
          physics Physics {
          }
        }
      ]
    }
    DEF DD HingeJoint {
      jointParameters HingeJointParameters {
        position 15.839993343406215
        axis 0 1 0
        anchor 0.03 -0.043 -6.01836e-05
      }
      device [
        PositionSensor {
          name "encoder3"
        }
        RotationalMotor {
          name "motor3"
        }
      ]
      endPoint Solid {
        translation 0.03 -0.043 -6.01836e-05
        rotation -0.04672464687432604 0.7059092584425598 -0.7067594542838073 3.234861860170931
        children [
          DEF M1 Shape {
            appearance Appearance {
              material Material {
                diffuseColor 0.1 0.1 0.1
              }
            }
            geometry Cylinder {
              height 0.015
              radius 0.018
            }
          }
        ]
        name "motor3"
        boundingObject USE M1
        physics Physics {
        }
      }
    }
    DEF DA HingeJoint {
      jointParameters HingeJointParameters {
        position 15.83999346476667
        axis 0 1 0
        anchor -0.02 -0.043 -6.01836e-05
      }
      device [
        PositionSensor {
          name "encoder4"
        }
        RotationalMotor {
          name "motor4"
        }
      ]
      endPoint Solid {
        translation -0.02 -0.043 -6.01836e-05
        rotation -0.04672468985405415 0.7059092570218418 -0.7067594528613774 3.234861945840399
        children [
          DEF M2 Shape {
            appearance Appearance {
              material Material {
                diffuseColor 0.1 0.1 0.1
              }
            }
            geometry Cylinder {
              height 0.015
              radius 0.018
            }
          }
        ]
        name "motor2"
        boundingObject USE M2
        physics Physics {
        }
      }
    }
    DEF ID HingeJoint {
      jointParameters HingeJointParameters {
        position 15.839993315540777
        axis 0 1 0
        anchor 0.03 0.043 6.01835e-05
      }
      device [
        PositionSensor {
          name "encoder1"
        }
        RotationalMotor {
          name "motor1"
        }
      ]
      endPoint Solid {
        translation 0.03 0.043 6.01835e-05
        rotation -0.046724637005798694 0.7059092587687692 -0.7067594546104091 3.23486184050046
        children [
          DEF M3 Shape {
            appearance Appearance {
              material Material {
                diffuseColor 0.1 0.1 0.1
              }
            }
            geometry Cylinder {
              height 0.015
              radius 0.018
            }
          }
        ]
        name "motor1"
        boundingObject USE M3
        physics Physics {
        }
      }
    }
    DEF IA HingeJoint {
      jointParameters HingeJointParameters {
        position 15.839993337115272
        axis 0 1 0
        anchor -0.02 0.043 6.01835e-05
      }
      device [
        PositionSensor {
          name "encoder2"
        }
        RotationalMotor {
          name "motor2"
        }
      ]
      endPoint Solid {
        translation -0.02 0.043 6.01835e-05
        rotation -0.04672464464639239 0.7059092585162055 -0.7067594543575412 3.234861855730095
        children [
          DEF M4 Shape {
            appearance Appearance {
              material Material {
                diffuseColor 0.1 0.1 0.1
              }
            }
            geometry Cylinder {
              height 0.015
              radius 0.018
            }
          }
        ]
        name "motor1(3)"
        boundingObject USE M4
        physics Physics {
        }
      }
    }
    DEF Body Shape {
      appearance Appearance {
        material Material {
          diffuseColor 0.1 0 0.1
        }
      }
      geometry Box {
        size 0.08 0.07 0.025
      }
    }
  ]
  name "robot(1)"
  boundingObject USE Body
  physics Physics {
  }
  controller "searching_controller"
}
Solid {
  children [
    Shape {
      appearance Appearance {
        material Material {
          diffuseColor 0 0 0
        }
      }
      geometry Cylinder {
        height 0.025
        radius 0.4235
      }
    }
  ]
  boundingObject Cylinder {
    height 0.025
    radius 0.4235
  }
}
Solid {
  children [
    Shape {
      geometry Cylinder {
        height 0.024
        radius 0.451
      }
    }
  ]
  name "solid(1)"
  boundingObject Cylinder {
    height 0.024
    radius 0.451
  }
}
